ypeError: Invalid comparison between dtype=datetime64[ns] and date
Traceback:
File "/home/runner/workspace/.pythonlibs/lib/python3.11/site-packages/streamlit/runtime/scriptrunner/exec_code.py", line 121, in exec_func_with_error_handling
    result = func()
             ^^^^^^
File "/home/runner/workspace/.pythonlibs/lib/python3.11/site-packages/streamlit/runtime/scriptrunner/script_runner.py", line 640, in code_to_exec
    exec(code, module.__dict__)
File "/home/runner/workspace/app.py", line 227, in <module>
    (filtered_df["Deadline"].dt.date >= start_date) &
    ^^^^^^^^^^^^^^^^^^^^^^^^^^^^^^^^^^^^^^^^^^^^^
File "/home/runner/workspace/.pythonlibs/lib/python3.11/site-packages/pandas/core/ops/common.py", line 76, in new_method
    return method(self, other)
           ^^^^^^^^^^^^^^^^^^^
File "/home/runner/workspace/.pythonlibs/lib/python3.11/site-packages/pandas/core/arraylike.py", line 60, in __ge__
    return self._cmp_method(other, operator.ge)
           ^^^^^^^^^^^^^^^^^^^^^^^^^^^^^^^^^^^^
File "/home/runner/workspace/.pythonlibs/lib/python3.11/site-packages/pandas/core/series.py", line 6119, in _cmp_method
    res_values = ops.comparison_op(lvalues, rvalues, op)
                 ^^^^^^^^^^^^^^^^^^^^^^^^^^^^^^^^^^^^^^^
File "/home/runner/workspace/.pythonlibs/lib/python3.11/site-packages/pandas/core/ops/array_ops.py", line 330, in comparison_op
    res_values = op(lvalues, rvalues)
                 ^^^^^^^^^^^^^^^^^^^^
File "/home/runner/workspace/.pythonlibs/lib/python3.11/site-packages/pandas/core/ops/common.py", line 76, in new_method
    return method(self, other)
           ^^^^^^^^^^^^^^^^^^^
File "/home/runner/workspace/.pythonlibs/lib/python3.11/site-packages/pandas/core/arraylike.py", line 60, in __ge__
    return self._cmp_method(other, operator.ge)
           ^^^^^^^^^^^^^^^^^^^^^^^^^^^^^^^^^^^^
File "/home/runner/workspace/.pythonlibs/lib/python3.11/site-packages/pandas/core/arrays/datetimelike.py", line 985, in _cmp_method
    return invalid_comparison(self, other, op)
           ^^^^^^^^^^^^^^^^^^^^^^^^^^^^^^^^^^^
File "/home/runner/workspace/.pythonlibs/lib/python3.11/site-packages/pandas/core/ops/invalid.py", line 40, in invalid_comparison
    raise TypeError(f"Invalid comparison between dtype={left.dtype} and {typ}")